[2025-08-10T13:03:11.447+0000] {local_task_job_runner.py:120} INFO - ::group::Pre task execution logs
[2025-08-10T13:03:11.475+0000] {taskinstance.py:2073} INFO - Dependencies all met for dep_context=non-requeueable deps ti=<TaskInstance: test.Alimentation_des_bases_de_données.mongo_ingection manual__2025-08-10T13:03:03.598971+00:00 [queued]>
[2025-08-10T13:03:11.483+0000] {taskinstance.py:2073} INFO - Dependencies all met for dep_context=requeueable deps ti=<TaskInstance: test.Alimentation_des_bases_de_données.mongo_ingection manual__2025-08-10T13:03:03.598971+00:00 [queued]>
[2025-08-10T13:03:11.483+0000] {taskinstance.py:2303} INFO - Starting attempt 1 of 1
[2025-08-10T13:03:11.496+0000] {taskinstance.py:2327} INFO - Executing <Task(PythonOperator): Alimentation_des_bases_de_données.mongo_ingection> on 2025-08-10 13:03:03.598971+00:00
[2025-08-10T13:03:11.506+0000] {logging_mixin.py:188} WARNING - /home/***/.local/lib/python3.12/site-packages/***/task/task_runner/standard_task_runner.py:61 DeprecationWarning: This process (pid=155) is multi-threaded, use of fork() may lead to deadlocks in the child.
[2025-08-10T13:03:11.507+0000] {standard_task_runner.py:63} INFO - Started process 168 to run task
[2025-08-10T13:03:11.506+0000] {standard_task_runner.py:90} INFO - Running: ['***', 'tasks', 'run', 'test', 'Alimentation_des_bases_de_données.mongo_ingection', 'manual__2025-08-10T13:03:03.598971+00:00', '--job-id', '51', '--raw', '--subdir', 'DAGS_FOLDER/PremierDagLake.py', '--cfg-path', '/tmp/tmp3_51l5rn']
[2025-08-10T13:03:11.508+0000] {standard_task_runner.py:91} INFO - Job 51: Subtask Alimentation_des_bases_de_données.mongo_ingection
[2025-08-10T13:03:11.521+0000] {logging_mixin.py:188} WARNING - /home/***/.local/lib/python3.12/site-packages/***/settings.py:195 DeprecationWarning: The sql_alchemy_conn option in [core] has been moved to the sql_alchemy_conn option in [database] - the old setting has been used, but please update your config.
[2025-08-10T13:03:11.557+0000] {task_command.py:426} INFO - Running <TaskInstance: test.Alimentation_des_bases_de_données.mongo_ingection manual__2025-08-10T13:03:03.598971+00:00 [running]> on host df13be40d8b2
[2025-08-10T13:03:11.639+0000] {taskinstance.py:2644} INFO - Exporting env vars: AIRFLOW_CTX_DAG_OWNER='***' AIRFLOW_CTX_DAG_ID='test' AIRFLOW_CTX_TASK_ID='Alimentation_des_bases_de_données.mongo_ingection' AIRFLOW_CTX_EXECUTION_DATE='2025-08-10T13:03:03.598971+00:00' AIRFLOW_CTX_TRY_NUMBER='1' AIRFLOW_CTX_DAG_RUN_ID='manual__2025-08-10T13:03:03.598971+00:00'
[2025-08-10T13:03:11.640+0000] {taskinstance.py:430} INFO - ::endgroup::
[2025-08-10T13:03:11.686+0000] {taskinstance.py:441} INFO - ::group::Post task execution logs
[2025-08-10T13:03:11.687+0000] {taskinstance.py:2890} ERROR - Task failed with exception
Traceback (most recent call last):
  File "/home/airflow/.local/lib/python3.12/site-packages/airflow/models/taskinstance.py", line 465, in _execute_task
    result = _execute_callable(context=context, **execute_callable_kwargs)
             ^^^^^^^^^^^^^^^^^^^^^^^^^^^^^^^^^^^^^^^^^^^^^^^^^^^^^^^^^^^^^
  File "/home/airflow/.local/lib/python3.12/site-packages/airflow/models/taskinstance.py", line 432, in _execute_callable
    return execute_callable(context=context, **execute_callable_kwargs)
           ^^^^^^^^^^^^^^^^^^^^^^^^^^^^^^^^^^^^^^^^^^^^^^^^^^^^^^^^^^^^
  File "/home/airflow/.local/lib/python3.12/site-packages/airflow/models/baseoperator.py", line 400, in wrapper
    return func(self, *args, **kwargs)
           ^^^^^^^^^^^^^^^^^^^^^^^^^^^
  File "/home/airflow/.local/lib/python3.12/site-packages/airflow/operators/python.py", line 235, in execute
    return_value = self.execute_callable()
                   ^^^^^^^^^^^^^^^^^^^^^^^
  File "/home/airflow/.local/lib/python3.12/site-packages/airflow/operators/python.py", line 252, in execute_callable
    return self.python_callable(*self.op_args, **self.op_kwargs)
           ^^^^^^^^^^^^^^^^^^^^^^^^^^^^^^^^^^^^^^^^^^^^^^^^^^^^^
  File "/opt/airflow/dags/PremierDagLake.py", line 126, in MongoIng
    gestion.creer_collection()
  File "/opt/airflow/src/utils_BD.py", line 154, in creer_collection
    collection.insert_many(donnees)
  File "/home/airflow/.local/lib/python3.12/site-packages/pymongo/_csot.py", line 108, in csot_wrapper
    return func(self, *args, **kwargs)
           ^^^^^^^^^^^^^^^^^^^^^^^^^^^
  File "/home/airflow/.local/lib/python3.12/site-packages/pymongo/collection.py", line 742, in insert_many
    blk.execute(write_concern, session, _Op.INSERT)
  File "/home/airflow/.local/lib/python3.12/site-packages/pymongo/bulk.py", line 595, in execute
    return self.execute_command(generator, write_concern, session, operation)
           ^^^^^^^^^^^^^^^^^^^^^^^^^^^^^^^^^^^^^^^^^^^^^^^^^^^^^^^^^^^^^^^^^^
  File "/home/airflow/.local/lib/python3.12/site-packages/pymongo/bulk.py", line 452, in execute_command
    client._retryable_write(
  File "/home/airflow/.local/lib/python3.12/site-packages/pymongo/mongo_client.py", line 1575, in _retryable_write
    return self._retry_with_session(retryable, func, s, bulk, operation, operation_id)
           ^^^^^^^^^^^^^^^^^^^^^^^^^^^^^^^^^^^^^^^^^^^^^^^^^^^^^^^^^^^^^^^^^^^^^^^^^^^
  File "/home/airflow/.local/lib/python3.12/site-packages/pymongo/mongo_client.py", line 1461, in _retry_with_session
    return self._retry_internal(
           ^^^^^^^^^^^^^^^^^^^^^
  File "/home/airflow/.local/lib/python3.12/site-packages/pymongo/_csot.py", line 108, in csot_wrapper
    return func(self, *args, **kwargs)
           ^^^^^^^^^^^^^^^^^^^^^^^^^^^
  File "/home/airflow/.local/lib/python3.12/site-packages/pymongo/mongo_client.py", line 1507, in _retry_internal
    ).run()
      ^^^^^
  File "/home/airflow/.local/lib/python3.12/site-packages/pymongo/mongo_client.py", line 2353, in run
    return self._read() if self._is_read else self._write()
                                              ^^^^^^^^^^^^^
  File "/home/airflow/.local/lib/python3.12/site-packages/pymongo/mongo_client.py", line 2457, in _write
    with self._client._checkout(self._server, self._session) as conn:
  File "/usr/local/lib/python3.12/contextlib.py", line 137, in __enter__
    return next(self.gen)
           ^^^^^^^^^^^^^^
  File "/home/airflow/.local/lib/python3.12/site-packages/pymongo/mongo_client.py", line 1266, in _checkout
    with server.checkout(handler=err_handler) as conn:
  File "/usr/local/lib/python3.12/contextlib.py", line 137, in __enter__
    return next(self.gen)
           ^^^^^^^^^^^^^^
  File "/home/airflow/.local/lib/python3.12/site-packages/pymongo/pool.py", line 1767, in checkout
    conn = self._get_conn(checkout_started_time, handler=handler)
           ^^^^^^^^^^^^^^^^^^^^^^^^^^^^^^^^^^^^^^^^^^^^^^^^^^^^^^
  File "/home/airflow/.local/lib/python3.12/site-packages/pymongo/pool.py", line 1926, in _get_conn
    conn = self.connect(handler=handler)
           ^^^^^^^^^^^^^^^^^^^^^^^^^^^^^
  File "/home/airflow/.local/lib/python3.12/site-packages/pymongo/pool.py", line 1729, in connect
    conn.authenticate()
  File "/home/airflow/.local/lib/python3.12/site-packages/pymongo/pool.py", line 1099, in authenticate
    auth.authenticate(creds, self, reauthenticate=reauthenticate)
  File "/home/airflow/.local/lib/python3.12/site-packages/pymongo/auth.py", line 656, in authenticate
    auth_func(credentials, conn)
  File "/home/airflow/.local/lib/python3.12/site-packages/pymongo/auth.py", line 560, in _authenticate_default
    return _authenticate_scram(credentials, conn, "SCRAM-SHA-1")
           ^^^^^^^^^^^^^^^^^^^^^^^^^^^^^^^^^^^^^^^^^^^^^^^^^^^^^
  File "/home/airflow/.local/lib/python3.12/site-packages/pymongo/auth.py", line 299, in _authenticate_scram
    res = conn.command(source, cmd)
          ^^^^^^^^^^^^^^^^^^^^^^^^^
  File "/home/airflow/.local/lib/python3.12/site-packages/pymongo/helpers.py", line 342, in inner
    return func(*args, **kwargs)
           ^^^^^^^^^^^^^^^^^^^^^
  File "/home/airflow/.local/lib/python3.12/site-packages/pymongo/pool.py", line 989, in command
    return command(
           ^^^^^^^^
  File "/home/airflow/.local/lib/python3.12/site-packages/pymongo/network.py", line 212, in command
    helpers._check_command_response(
  File "/home/airflow/.local/lib/python3.12/site-packages/pymongo/helpers.py", line 248, in _check_command_response
    raise OperationFailure(errmsg, code, response, max_wire_version)
pymongo.errors.OperationFailure: Authentication failed., full error: {'ok': 0.0, 'errmsg': 'Authentication failed.', 'code': 18, 'codeName': 'AuthenticationFailed'}
[2025-08-10T13:03:11.828+0000] {taskinstance.py:1205} INFO - Marking task as FAILED. dag_id=test, task_id=Alimentation_des_bases_de_données.mongo_ingection, execution_date=20250810T130303, start_date=20250810T130311, end_date=20250810T130311
[2025-08-10T13:03:11.841+0000] {standard_task_runner.py:110} ERROR - Failed to execute job 51 for task Alimentation_des_bases_de_données.mongo_ingection (Authentication failed., full error: {'ok': 0.0, 'errmsg': 'Authentication failed.', 'code': 18, 'codeName': 'AuthenticationFailed'}; 168)
[2025-08-10T13:03:11.882+0000] {local_task_job_runner.py:240} INFO - Task exited with return code 1
[2025-08-10T13:03:11.905+0000] {taskinstance.py:3482} INFO - 0 downstream tasks scheduled from follow-on schedule check
[2025-08-10T13:03:11.907+0000] {local_task_job_runner.py:222} INFO - ::endgroup::
