[2025-08-10T12:20:08.343+0000] {local_task_job_runner.py:120} INFO - ::group::Pre task execution logs
[2025-08-10T12:20:08.370+0000] {taskinstance.py:2073} INFO - Dependencies all met for dep_context=non-requeueable deps ti=<TaskInstance: test.Alimentation_des_bases_de_données.mongo_ingection manual__2025-08-10T12:20:01.141479+00:00 [queued]>
[2025-08-10T12:20:08.378+0000] {taskinstance.py:2073} INFO - Dependencies all met for dep_context=requeueable deps ti=<TaskInstance: test.Alimentation_des_bases_de_données.mongo_ingection manual__2025-08-10T12:20:01.141479+00:00 [queued]>
[2025-08-10T12:20:08.378+0000] {taskinstance.py:2303} INFO - Starting attempt 1 of 1
[2025-08-10T12:20:08.391+0000] {taskinstance.py:2327} INFO - Executing <Task(PythonOperator): Alimentation_des_bases_de_données.mongo_ingection> on 2025-08-10 12:20:01.141479+00:00
[2025-08-10T12:20:08.401+0000] {logging_mixin.py:188} WARNING - /home/***/.local/lib/python3.12/site-packages/***/task/task_runner/standard_task_runner.py:61 DeprecationWarning: This process (pid=783) is multi-threaded, use of fork() may lead to deadlocks in the child.
[2025-08-10T12:20:08.402+0000] {standard_task_runner.py:63} INFO - Started process 796 to run task
[2025-08-10T12:20:08.402+0000] {standard_task_runner.py:90} INFO - Running: ['***', 'tasks', 'run', 'test', 'Alimentation_des_bases_de_données.mongo_ingection', 'manual__2025-08-10T12:20:01.141479+00:00', '--job-id', '28', '--raw', '--subdir', 'DAGS_FOLDER/PremierDagLake.py', '--cfg-path', '/tmp/tmppfc6occy']
[2025-08-10T12:20:08.404+0000] {standard_task_runner.py:91} INFO - Job 28: Subtask Alimentation_des_bases_de_données.mongo_ingection
[2025-08-10T12:20:08.413+0000] {logging_mixin.py:188} WARNING - /home/***/.local/lib/python3.12/site-packages/***/settings.py:195 DeprecationWarning: The sql_alchemy_conn option in [core] has been moved to the sql_alchemy_conn option in [database] - the old setting has been used, but please update your config.
[2025-08-10T12:20:08.452+0000] {task_command.py:426} INFO - Running <TaskInstance: test.Alimentation_des_bases_de_données.mongo_ingection manual__2025-08-10T12:20:01.141479+00:00 [running]> on host b798844a50be
[2025-08-10T12:20:08.557+0000] {taskinstance.py:2644} INFO - Exporting env vars: AIRFLOW_CTX_DAG_OWNER='***' AIRFLOW_CTX_DAG_ID='test' AIRFLOW_CTX_TASK_ID='Alimentation_des_bases_de_données.mongo_ingection' AIRFLOW_CTX_EXECUTION_DATE='2025-08-10T12:20:01.141479+00:00' AIRFLOW_CTX_TRY_NUMBER='1' AIRFLOW_CTX_DAG_RUN_ID='manual__2025-08-10T12:20:01.141479+00:00'
[2025-08-10T12:20:08.558+0000] {taskinstance.py:430} INFO - ::endgroup::
[2025-08-10T12:20:08.560+0000] {taskinstance.py:441} INFO - ::group::Post task execution logs
[2025-08-10T12:20:08.560+0000] {taskinstance.py:2890} ERROR - Task failed with exception
Traceback (most recent call last):
  File "/home/airflow/.local/lib/python3.12/site-packages/airflow/models/taskinstance.py", line 465, in _execute_task
    result = _execute_callable(context=context, **execute_callable_kwargs)
             ^^^^^^^^^^^^^^^^^^^^^^^^^^^^^^^^^^^^^^^^^^^^^^^^^^^^^^^^^^^^^
  File "/home/airflow/.local/lib/python3.12/site-packages/airflow/models/taskinstance.py", line 432, in _execute_callable
    return execute_callable(context=context, **execute_callable_kwargs)
           ^^^^^^^^^^^^^^^^^^^^^^^^^^^^^^^^^^^^^^^^^^^^^^^^^^^^^^^^^^^^
  File "/home/airflow/.local/lib/python3.12/site-packages/airflow/models/baseoperator.py", line 400, in wrapper
    return func(self, *args, **kwargs)
           ^^^^^^^^^^^^^^^^^^^^^^^^^^^
  File "/home/airflow/.local/lib/python3.12/site-packages/airflow/operators/python.py", line 235, in execute
    return_value = self.execute_callable()
                   ^^^^^^^^^^^^^^^^^^^^^^^
  File "/home/airflow/.local/lib/python3.12/site-packages/airflow/operators/python.py", line 252, in execute_callable
    return self.python_callable(*self.op_args, **self.op_kwargs)
           ^^^^^^^^^^^^^^^^^^^^^^^^^^^^^^^^^^^^^^^^^^^^^^^^^^^^^
  File "/opt/airflow/dags/PremierDagLake.py", line 125, in MongoIng
    gestion = Gestion_des_donnees(doc)
              ^^^^^^^^^^^^^^^^^^^^^^^^
  File "/opt/airflow/src/utils_BD.py", line 12, in __init__
    self.mongo_connection = self.get_mongoCon()
                           ^^^^^^^^^^^^^^^^^^^
  File "/opt/airflow/src/utils_BD.py", line 40, in get_mongoCon
    port = int(os.getenv('Port_interneMongo'))
           ^^^^^^^^^^^^^^^^^^^^^^^^^^^^^^^^^^^
TypeError: int() argument must be a string, a bytes-like object or a real number, not 'NoneType'
[2025-08-10T12:20:08.575+0000] {taskinstance.py:1205} INFO - Marking task as FAILED. dag_id=test, task_id=Alimentation_des_bases_de_données.mongo_ingection, execution_date=20250810T122001, start_date=20250810T122008, end_date=20250810T122008
[2025-08-10T12:20:08.590+0000] {standard_task_runner.py:110} ERROR - Failed to execute job 28 for task Alimentation_des_bases_de_données.mongo_ingection (int() argument must be a string, a bytes-like object or a real number, not 'NoneType'; 796)
[2025-08-10T12:20:08.616+0000] {local_task_job_runner.py:240} INFO - Task exited with return code 1
[2025-08-10T12:20:08.649+0000] {taskinstance.py:3482} INFO - 0 downstream tasks scheduled from follow-on schedule check
[2025-08-10T12:20:08.652+0000] {local_task_job_runner.py:222} INFO - ::endgroup::
