[2025-08-10T11:52:10.053+0000] {local_task_job_runner.py:120} INFO - ::group::Pre task execution logs
[2025-08-10T11:52:10.079+0000] {taskinstance.py:2073} INFO - Dependencies all met for dep_context=non-requeueable deps ti=<TaskInstance: Premier_dag.Alimentation_des_bases_de_données.mongo_ingection manual__2025-08-10T11:44:32.531587+00:00 [queued]>
[2025-08-10T11:52:10.087+0000] {taskinstance.py:2073} INFO - Dependencies all met for dep_context=requeueable deps ti=<TaskInstance: Premier_dag.Alimentation_des_bases_de_données.mongo_ingection manual__2025-08-10T11:44:32.531587+00:00 [queued]>
[2025-08-10T11:52:10.088+0000] {taskinstance.py:2303} INFO - Starting attempt 1 of 1
[2025-08-10T11:52:10.100+0000] {taskinstance.py:2327} INFO - Executing <Task(PythonOperator): Alimentation_des_bases_de_données.mongo_ingection> on 2025-08-10 11:44:32.531587+00:00
[2025-08-10T11:52:10.109+0000] {logging_mixin.py:188} WARNING - /home/***/.local/lib/python3.12/site-packages/***/task/task_runner/standard_task_runner.py:61 DeprecationWarning: This process (pid=463) is multi-threaded, use of fork() may lead to deadlocks in the child.
[2025-08-10T11:52:10.110+0000] {standard_task_runner.py:63} INFO - Started process 476 to run task
[2025-08-10T11:52:10.109+0000] {standard_task_runner.py:90} INFO - Running: ['***', 'tasks', 'run', 'Premier_dag', 'Alimentation_des_bases_de_données.mongo_ingection', 'manual__2025-08-10T11:44:32.531587+00:00', '--job-id', '13', '--raw', '--subdir', 'DAGS_FOLDER/PremierDagLake.py', '--cfg-path', '/tmp/tmp3i0xggyn']
[2025-08-10T11:52:10.111+0000] {standard_task_runner.py:91} INFO - Job 13: Subtask Alimentation_des_bases_de_données.mongo_ingection
[2025-08-10T11:52:10.124+0000] {logging_mixin.py:188} WARNING - /home/***/.local/lib/python3.12/site-packages/***/settings.py:195 DeprecationWarning: The sql_alchemy_conn option in [core] has been moved to the sql_alchemy_conn option in [database] - the old setting has been used, but please update your config.
[2025-08-10T11:52:10.162+0000] {task_command.py:426} INFO - Running <TaskInstance: Premier_dag.Alimentation_des_bases_de_données.mongo_ingection manual__2025-08-10T11:44:32.531587+00:00 [running]> on host b798844a50be
[2025-08-10T11:52:10.254+0000] {taskinstance.py:2644} INFO - Exporting env vars: AIRFLOW_CTX_DAG_OWNER='***' AIRFLOW_CTX_DAG_ID='Premier_dag' AIRFLOW_CTX_TASK_ID='Alimentation_des_bases_de_données.mongo_ingection' AIRFLOW_CTX_EXECUTION_DATE='2025-08-10T11:44:32.531587+00:00' AIRFLOW_CTX_TRY_NUMBER='1' AIRFLOW_CTX_DAG_RUN_ID='manual__2025-08-10T11:44:32.531587+00:00'
[2025-08-10T11:52:10.255+0000] {taskinstance.py:430} INFO - ::endgroup::
[2025-08-10T11:52:10.257+0000] {taskinstance.py:441} INFO - ::group::Post task execution logs
[2025-08-10T11:52:10.257+0000] {taskinstance.py:2890} ERROR - Task failed with exception
Traceback (most recent call last):
  File "/home/airflow/.local/lib/python3.12/site-packages/airflow/models/taskinstance.py", line 465, in _execute_task
    result = _execute_callable(context=context, **execute_callable_kwargs)
             ^^^^^^^^^^^^^^^^^^^^^^^^^^^^^^^^^^^^^^^^^^^^^^^^^^^^^^^^^^^^^
  File "/home/airflow/.local/lib/python3.12/site-packages/airflow/models/taskinstance.py", line 432, in _execute_callable
    return execute_callable(context=context, **execute_callable_kwargs)
           ^^^^^^^^^^^^^^^^^^^^^^^^^^^^^^^^^^^^^^^^^^^^^^^^^^^^^^^^^^^^
  File "/home/airflow/.local/lib/python3.12/site-packages/airflow/models/baseoperator.py", line 400, in wrapper
    return func(self, *args, **kwargs)
           ^^^^^^^^^^^^^^^^^^^^^^^^^^^
  File "/home/airflow/.local/lib/python3.12/site-packages/airflow/operators/python.py", line 235, in execute
    return_value = self.execute_callable()
                   ^^^^^^^^^^^^^^^^^^^^^^^
  File "/home/airflow/.local/lib/python3.12/site-packages/airflow/operators/python.py", line 252, in execute_callable
    return self.python_callable(*self.op_args, **self.op_kwargs)
           ^^^^^^^^^^^^^^^^^^^^^^^^^^^^^^^^^^^^^^^^^^^^^^^^^^^^^
  File "/opt/airflow/dags/PremierDagLake.py", line 68, in MongoIng
    gestion = Gestion_des_donnees(doc)
              ^^^^^^^^^^^^^^^^^^^^^^^^
  File "/opt/airflow/src/utils_BD.py", line 12, in __init__
    self.mongo_connection = self.get_mongoCon()
                           ^^^^^^^^^^^^^^^^^^^
  File "/opt/airflow/src/utils_BD.py", line 42, in get_mongoCon
    client = MongoClient(uri)
             ^^^^^^^^^^^^^^^^
  File "/home/airflow/.local/lib/python3.12/site-packages/pymongo/mongo_client.py", line 774, in __init__
    res = uri_parser.parse_uri(
          ^^^^^^^^^^^^^^^^^^^^^
  File "/home/airflow/.local/lib/python3.12/site-packages/pymongo/uri_parser.py", line 568, in parse_uri
    nodes = split_hosts(hosts, default_port=default_port)
            ^^^^^^^^^^^^^^^^^^^^^^^^^^^^^^^^^^^^^^^^^^^^^
  File "/home/airflow/.local/lib/python3.12/site-packages/pymongo/uri_parser.py", line 381, in split_hosts
    nodes.append(parse_host(entity, port))
                 ^^^^^^^^^^^^^^^^^^^^^^^^
  File "/home/airflow/.local/lib/python3.12/site-packages/pymongo/uri_parser.py", line 147, in parse_host
    raise ValueError(f"Port must be an integer between 0 and 65535: {port!r}")
ValueError: Port must be an integer between 0 and 65535: 'None'
[2025-08-10T11:52:10.270+0000] {taskinstance.py:1205} INFO - Marking task as FAILED. dag_id=Premier_dag, task_id=Alimentation_des_bases_de_données.mongo_ingection, execution_date=20250810T114432, start_date=20250810T115210, end_date=20250810T115210
[2025-08-10T11:52:10.281+0000] {standard_task_runner.py:110} ERROR - Failed to execute job 13 for task Alimentation_des_bases_de_données.mongo_ingection (Port must be an integer between 0 and 65535: 'None'; 476)
[2025-08-10T11:52:10.324+0000] {local_task_job_runner.py:240} INFO - Task exited with return code 1
[2025-08-10T11:52:10.339+0000] {taskinstance.py:3482} INFO - 0 downstream tasks scheduled from follow-on schedule check
[2025-08-10T11:52:10.340+0000] {local_task_job_runner.py:222} INFO - ::endgroup::
