[2025-08-10T12:19:37.499+0000] {local_task_job_runner.py:120} INFO - ::group::Pre task execution logs
[2025-08-10T12:19:37.525+0000] {taskinstance.py:2073} INFO - Dependencies all met for dep_context=non-requeueable deps ti=<TaskInstance: test.Alimentation_des_bases_de_données.Postgres_Ingection manual__2025-08-10T12:19:28.854594+00:00 [queued]>
[2025-08-10T12:19:37.533+0000] {taskinstance.py:2073} INFO - Dependencies all met for dep_context=requeueable deps ti=<TaskInstance: test.Alimentation_des_bases_de_données.Postgres_Ingection manual__2025-08-10T12:19:28.854594+00:00 [queued]>
[2025-08-10T12:19:37.533+0000] {taskinstance.py:2303} INFO - Starting attempt 1 of 1
[2025-08-10T12:19:37.541+0000] {taskinstance.py:2327} INFO - Executing <Task(PythonOperator): Alimentation_des_bases_de_données.Postgres_Ingection> on 2025-08-10 12:19:28.854594+00:00
[2025-08-10T12:19:37.552+0000] {logging_mixin.py:188} WARNING - /home/***/.local/lib/python3.12/site-packages/***/task/task_runner/standard_task_runner.py:61 DeprecationWarning: This process (pid=683) is multi-threaded, use of fork() may lead to deadlocks in the child.
[2025-08-10T12:19:37.554+0000] {standard_task_runner.py:63} INFO - Started process 696 to run task
[2025-08-10T12:19:37.552+0000] {standard_task_runner.py:90} INFO - Running: ['***', 'tasks', 'run', 'test', 'Alimentation_des_bases_de_données.Postgres_Ingection', 'manual__2025-08-10T12:19:28.854594+00:00', '--job-id', '21', '--raw', '--subdir', 'DAGS_FOLDER/PremierDagLake.py', '--cfg-path', '/tmp/tmppbny63q0']
[2025-08-10T12:19:37.555+0000] {standard_task_runner.py:91} INFO - Job 21: Subtask Alimentation_des_bases_de_données.Postgres_Ingection
[2025-08-10T12:19:37.568+0000] {logging_mixin.py:188} WARNING - /home/***/.local/lib/python3.12/site-packages/***/settings.py:195 DeprecationWarning: The sql_alchemy_conn option in [core] has been moved to the sql_alchemy_conn option in [database] - the old setting has been used, but please update your config.
[2025-08-10T12:19:37.603+0000] {task_command.py:426} INFO - Running <TaskInstance: test.Alimentation_des_bases_de_données.Postgres_Ingection manual__2025-08-10T12:19:28.854594+00:00 [running]> on host b798844a50be
[2025-08-10T12:19:37.682+0000] {taskinstance.py:2644} INFO - Exporting env vars: AIRFLOW_CTX_DAG_OWNER='***' AIRFLOW_CTX_DAG_ID='test' AIRFLOW_CTX_TASK_ID='Alimentation_des_bases_de_données.Postgres_Ingection' AIRFLOW_CTX_EXECUTION_DATE='2025-08-10T12:19:28.854594+00:00' AIRFLOW_CTX_TRY_NUMBER='1' AIRFLOW_CTX_DAG_RUN_ID='manual__2025-08-10T12:19:28.854594+00:00'
[2025-08-10T12:19:37.683+0000] {taskinstance.py:430} INFO - ::endgroup::
[2025-08-10T12:19:37.684+0000] {taskinstance.py:441} INFO - ::group::Post task execution logs
[2025-08-10T12:19:37.685+0000] {taskinstance.py:2890} ERROR - Task failed with exception
Traceback (most recent call last):
  File "/home/airflow/.local/lib/python3.12/site-packages/airflow/models/taskinstance.py", line 465, in _execute_task
    result = _execute_callable(context=context, **execute_callable_kwargs)
             ^^^^^^^^^^^^^^^^^^^^^^^^^^^^^^^^^^^^^^^^^^^^^^^^^^^^^^^^^^^^^
  File "/home/airflow/.local/lib/python3.12/site-packages/airflow/models/taskinstance.py", line 432, in _execute_callable
    return execute_callable(context=context, **execute_callable_kwargs)
           ^^^^^^^^^^^^^^^^^^^^^^^^^^^^^^^^^^^^^^^^^^^^^^^^^^^^^^^^^^^^
  File "/home/airflow/.local/lib/python3.12/site-packages/airflow/models/baseoperator.py", line 400, in wrapper
    return func(self, *args, **kwargs)
           ^^^^^^^^^^^^^^^^^^^^^^^^^^^
  File "/home/airflow/.local/lib/python3.12/site-packages/airflow/operators/python.py", line 235, in execute
    return_value = self.execute_callable()
                   ^^^^^^^^^^^^^^^^^^^^^^^
  File "/home/airflow/.local/lib/python3.12/site-packages/airflow/operators/python.py", line 252, in execute_callable
    return self.python_callable(*self.op_args, **self.op_kwargs)
           ^^^^^^^^^^^^^^^^^^^^^^^^^^^^^^^^^^^^^^^^^^^^^^^^^^^^^
  File "/opt/airflow/dags/PremierDagLake.py", line 114, in Postgres_Inge
    gestion = Gestion_des_donnees(doc)
              ^^^^^^^^^^^^^^^^^^^^^^^^
  File "/opt/airflow/src/utils_BD.py", line 12, in __init__
    self.mongo_connection = self.get_mongoCon()
                           ^^^^^^^^^^^^^^^^^^^
  File "/opt/airflow/src/utils_BD.py", line 40, in get_mongoCon
    port = int(os.getenv('Port_interneMongo'))
           ^^^^^^^^^^^^^^^^^^^^^^^^^^^^^^^^^^^
TypeError: int() argument must be a string, a bytes-like object or a real number, not 'NoneType'
[2025-08-10T12:19:37.696+0000] {taskinstance.py:1205} INFO - Marking task as FAILED. dag_id=test, task_id=Alimentation_des_bases_de_données.Postgres_Ingection, execution_date=20250810T121928, start_date=20250810T121937, end_date=20250810T121937
[2025-08-10T12:19:37.708+0000] {standard_task_runner.py:110} ERROR - Failed to execute job 21 for task Alimentation_des_bases_de_données.Postgres_Ingection (int() argument must be a string, a bytes-like object or a real number, not 'NoneType'; 696)
[2025-08-10T12:19:37.728+0000] {local_task_job_runner.py:240} INFO - Task exited with return code 1
[2025-08-10T12:19:37.752+0000] {taskinstance.py:3482} INFO - 0 downstream tasks scheduled from follow-on schedule check
[2025-08-10T12:19:37.754+0000] {local_task_job_runner.py:222} INFO - ::endgroup::
