[2025-07-30T11:32:18.721+0000] {local_task_job_runner.py:120} INFO - ::group::Pre task execution logs
[2025-07-30T11:32:18.872+0000] {taskinstance.py:2073} INFO - Dependencies all met for dep_context=non-requeueable deps ti=<TaskInstance: Premier_dag.end manual__2025-07-30T11:24:12.682717+00:00 [queued]>
[2025-07-30T11:32:18.892+0000] {taskinstance.py:2073} INFO - Dependencies all met for dep_context=requeueable deps ti=<TaskInstance: Premier_dag.end manual__2025-07-30T11:24:12.682717+00:00 [queued]>
[2025-07-30T11:32:18.893+0000] {taskinstance.py:2303} INFO - Starting attempt 1 of 1
[2025-07-30T11:32:18.922+0000] {taskinstance.py:2327} INFO - Executing <Task(BashOperator): end> on 2025-07-30 11:24:12.682717+00:00
[2025-07-30T11:32:18.937+0000] {standard_task_runner.py:63} INFO - Started process 105 to run task
[2025-07-30T11:32:18.943+0000] {standard_task_runner.py:90} INFO - Running: ['***', 'tasks', 'run', 'Premier_dag', 'end', 'manual__2025-07-30T11:24:12.682717+00:00', '--job-id', '5', '--raw', '--subdir', 'DAGS_FOLDER/PremierDagLake.py', '--cfg-path', '/tmp/tmp16n52_n4']
[2025-07-30T11:32:18.948+0000] {standard_task_runner.py:91} INFO - Job 5: Subtask end
[2025-07-30T11:32:18.982+0000] {logging_mixin.py:188} WARNING - /home/***/.local/lib/python3.12/site-packages/***/settings.py:195 DeprecationWarning: The sql_alchemy_conn option in [core] has been moved to the sql_alchemy_conn option in [database] - the old setting has been used, but please update your config.
[2025-07-30T11:32:19.067+0000] {task_command.py:426} INFO - Running <TaskInstance: Premier_dag.end manual__2025-07-30T11:24:12.682717+00:00 [running]> on host b11761e743d4
[2025-07-30T11:32:19.239+0000] {taskinstance.py:2644} INFO - Exporting env vars: AIRFLOW_CTX_DAG_OWNER='***' AIRFLOW_CTX_DAG_ID='Premier_dag' AIRFLOW_CTX_TASK_ID='end' AIRFLOW_CTX_EXECUTION_DATE='2025-07-30T11:24:12.682717+00:00' AIRFLOW_CTX_TRY_NUMBER='1' AIRFLOW_CTX_DAG_RUN_ID='manual__2025-07-30T11:24:12.682717+00:00'
[2025-07-30T11:32:19.241+0000] {taskinstance.py:430} INFO - ::endgroup::
[2025-07-30T11:32:19.242+0000] {subprocess.py:63} INFO - Tmp dir root location: /tmp
[2025-07-30T11:32:19.244+0000] {subprocess.py:75} INFO - Running command: ['/usr/bin/bash', '-c', 'echo fin (love and peace)']
[2025-07-30T11:32:19.269+0000] {subprocess.py:86} INFO - Output:
[2025-07-30T11:32:19.272+0000] {subprocess.py:93} INFO - /usr/bin/bash: -c: line 1: syntax error near unexpected token `('
[2025-07-30T11:32:19.273+0000] {subprocess.py:93} INFO - /usr/bin/bash: -c: line 1: `echo fin (love and peace)'
[2025-07-30T11:32:19.273+0000] {subprocess.py:97} INFO - Command exited with return code 2
[2025-07-30T11:32:19.274+0000] {taskinstance.py:441} INFO - ::group::Post task execution logs
[2025-07-30T11:32:19.298+0000] {taskinstance.py:2890} ERROR - Task failed with exception
Traceback (most recent call last):
  File "/home/airflow/.local/lib/python3.12/site-packages/airflow/models/taskinstance.py", line 465, in _execute_task
    result = _execute_callable(context=context, **execute_callable_kwargs)
             ^^^^^^^^^^^^^^^^^^^^^^^^^^^^^^^^^^^^^^^^^^^^^^^^^^^^^^^^^^^^^
  File "/home/airflow/.local/lib/python3.12/site-packages/airflow/models/taskinstance.py", line 432, in _execute_callable
    return execute_callable(context=context, **execute_callable_kwargs)
           ^^^^^^^^^^^^^^^^^^^^^^^^^^^^^^^^^^^^^^^^^^^^^^^^^^^^^^^^^^^^
  File "/home/airflow/.local/lib/python3.12/site-packages/airflow/models/baseoperator.py", line 400, in wrapper
    return func(self, *args, **kwargs)
           ^^^^^^^^^^^^^^^^^^^^^^^^^^^
  File "/home/airflow/.local/lib/python3.12/site-packages/airflow/operators/bash.py", line 243, in execute
    raise AirflowException(
airflow.exceptions.AirflowException: Bash command failed. The command returned a non-zero exit code 2.
[2025-07-30T11:32:19.309+0000] {taskinstance.py:1205} INFO - Marking task as FAILED. dag_id=Premier_dag, task_id=end, execution_date=20250730T112412, start_date=20250730T113218, end_date=20250730T113219
[2025-07-30T11:32:19.335+0000] {standard_task_runner.py:110} ERROR - Failed to execute job 5 for task end (Bash command failed. The command returned a non-zero exit code 2.; 105)
[2025-07-30T11:32:19.356+0000] {local_task_job_runner.py:240} INFO - Task exited with return code 1
[2025-07-30T11:32:19.398+0000] {taskinstance.py:3482} INFO - 0 downstream tasks scheduled from follow-on schedule check
[2025-07-30T11:32:19.401+0000] {local_task_job_runner.py:222} INFO - ::endgroup::
