[2025-08-10T12:21:31.778+0000] {local_task_job_runner.py:120} INFO - ::group::Pre task execution logs
[2025-08-10T12:21:31.804+0000] {taskinstance.py:2073} INFO - Dependencies all met for dep_context=non-requeueable deps ti=<TaskInstance: test.Alimentation_des_bases_de_données.mongo_ingection manual__2025-08-10T12:21:24.549909+00:00 [queued]>
[2025-08-10T12:21:31.813+0000] {taskinstance.py:2073} INFO - Dependencies all met for dep_context=requeueable deps ti=<TaskInstance: test.Alimentation_des_bases_de_données.mongo_ingection manual__2025-08-10T12:21:24.549909+00:00 [queued]>
[2025-08-10T12:21:31.813+0000] {taskinstance.py:2303} INFO - Starting attempt 1 of 1
[2025-08-10T12:21:31.824+0000] {taskinstance.py:2327} INFO - Executing <Task(PythonOperator): Alimentation_des_bases_de_données.mongo_ingection> on 2025-08-10 12:21:24.549909+00:00
[2025-08-10T12:21:31.830+0000] {logging_mixin.py:188} WARNING - /home/***/.local/lib/python3.12/site-packages/***/task/task_runner/standard_task_runner.py:61 DeprecationWarning: This process (pid=836) is multi-threaded, use of fork() may lead to deadlocks in the child.
[2025-08-10T12:21:31.831+0000] {standard_task_runner.py:63} INFO - Started process 849 to run task
[2025-08-10T12:21:31.831+0000] {standard_task_runner.py:90} INFO - Running: ['***', 'tasks', 'run', 'test', 'Alimentation_des_bases_de_données.mongo_ingection', 'manual__2025-08-10T12:21:24.549909+00:00', '--job-id', '31', '--raw', '--subdir', 'DAGS_FOLDER/PremierDagLake.py', '--cfg-path', '/tmp/tmpi32hg8st']
[2025-08-10T12:21:31.833+0000] {standard_task_runner.py:91} INFO - Job 31: Subtask Alimentation_des_bases_de_données.mongo_ingection
[2025-08-10T12:21:31.846+0000] {logging_mixin.py:188} WARNING - /home/***/.local/lib/python3.12/site-packages/***/settings.py:195 DeprecationWarning: The sql_alchemy_conn option in [core] has been moved to the sql_alchemy_conn option in [database] - the old setting has been used, but please update your config.
[2025-08-10T12:21:31.887+0000] {task_command.py:426} INFO - Running <TaskInstance: test.Alimentation_des_bases_de_données.mongo_ingection manual__2025-08-10T12:21:24.549909+00:00 [running]> on host b798844a50be
[2025-08-10T12:21:31.988+0000] {taskinstance.py:2644} INFO - Exporting env vars: AIRFLOW_CTX_DAG_OWNER='***' AIRFLOW_CTX_DAG_ID='test' AIRFLOW_CTX_TASK_ID='Alimentation_des_bases_de_données.mongo_ingection' AIRFLOW_CTX_EXECUTION_DATE='2025-08-10T12:21:24.549909+00:00' AIRFLOW_CTX_TRY_NUMBER='1' AIRFLOW_CTX_DAG_RUN_ID='manual__2025-08-10T12:21:24.549909+00:00'
[2025-08-10T12:21:31.989+0000] {taskinstance.py:430} INFO - ::endgroup::
[2025-08-10T12:21:32.004+0000] {taskinstance.py:441} INFO - ::group::Post task execution logs
[2025-08-10T12:21:32.005+0000] {taskinstance.py:2890} ERROR - Task failed with exception
Traceback (most recent call last):
  File "/home/airflow/.local/lib/python3.12/site-packages/airflow/models/taskinstance.py", line 465, in _execute_task
    result = _execute_callable(context=context, **execute_callable_kwargs)
             ^^^^^^^^^^^^^^^^^^^^^^^^^^^^^^^^^^^^^^^^^^^^^^^^^^^^^^^^^^^^^
  File "/home/airflow/.local/lib/python3.12/site-packages/airflow/models/taskinstance.py", line 432, in _execute_callable
    return execute_callable(context=context, **execute_callable_kwargs)
           ^^^^^^^^^^^^^^^^^^^^^^^^^^^^^^^^^^^^^^^^^^^^^^^^^^^^^^^^^^^^
  File "/home/airflow/.local/lib/python3.12/site-packages/airflow/models/baseoperator.py", line 400, in wrapper
    return func(self, *args, **kwargs)
           ^^^^^^^^^^^^^^^^^^^^^^^^^^^
  File "/home/airflow/.local/lib/python3.12/site-packages/airflow/operators/python.py", line 235, in execute
    return_value = self.execute_callable()
                   ^^^^^^^^^^^^^^^^^^^^^^^
  File "/home/airflow/.local/lib/python3.12/site-packages/airflow/operators/python.py", line 252, in execute_callable
    return self.python_callable(*self.op_args, **self.op_kwargs)
           ^^^^^^^^^^^^^^^^^^^^^^^^^^^^^^^^^^^^^^^^^^^^^^^^^^^^^
  File "/opt/airflow/dags/PremierDagLake.py", line 125, in MongoIng
    gestion = Gestion_des_donnees(doc)
              ^^^^^^^^^^^^^^^^^^^^^^^^
  File "/opt/airflow/src/utils_BD.py", line 14, in __init__
    self.mysql_connection = self.get_mysql_conn()
                            ^^^^^^^^^^^^^^^^^^^^^
  File "/opt/airflow/src/utils_BD.py", line 24, in get_mysql_conn
    return create_engine(f"mysql+pymysql://{user}:{password}@{host}:{port}/{db}")
           ^^^^^^^^^^^^^^^^^^^^^^^^^^^^^^^^^^^^^^^^^^^^^^^^^^^^^^^^^^^^^^^^^^^^^^
  File "<string>", line 2, in create_engine
  File "/home/airflow/.local/lib/python3.12/site-packages/sqlalchemy/util/deprecations.py", line 375, in warned
    return fn(*args, **kwargs)
           ^^^^^^^^^^^^^^^^^^^
  File "/home/airflow/.local/lib/python3.12/site-packages/sqlalchemy/engine/create.py", line 544, in create_engine
    dbapi = dialect_cls.dbapi(**dbapi_args)
            ^^^^^^^^^^^^^^^^^^^^^^^^^^^^^^^
  File "/home/airflow/.local/lib/python3.12/site-packages/sqlalchemy/dialects/mysql/pymysql.py", line 80, in dbapi
    return __import__("pymysql")
           ^^^^^^^^^^^^^^^^^^^^^
ModuleNotFoundError: No module named 'pymysql'
[2025-08-10T12:21:32.015+0000] {taskinstance.py:1205} INFO - Marking task as FAILED. dag_id=test, task_id=Alimentation_des_bases_de_données.mongo_ingection, execution_date=20250810T122124, start_date=20250810T122131, end_date=20250810T122132
[2025-08-10T12:21:32.024+0000] {standard_task_runner.py:110} ERROR - Failed to execute job 31 for task Alimentation_des_bases_de_données.mongo_ingection (No module named 'pymysql'; 849)
[2025-08-10T12:21:32.045+0000] {local_task_job_runner.py:240} INFO - Task exited with return code 1
[2025-08-10T12:21:32.070+0000] {taskinstance.py:3482} INFO - 0 downstream tasks scheduled from follow-on schedule check
[2025-08-10T12:21:32.072+0000] {local_task_job_runner.py:222} INFO - ::endgroup::
